Workbook

Sheet Executive_Summary
A1: Preguntas contestadas.
A3: Costos totales de transporte para el torneo | D3: =SUM(Calculation_Engine!$L$136:$L$159) -> 22587
A7: Costo totales de los favoritos
A8: Meda Maddix | D8: =SUMIF(Calculation_Engine!$A$136:$A$159,A8,Calculation_Engine!$L$136:$L$159) -> 1682
A9: Gaynell Lehrman | D9: =SUMIF(Calculation_Engine!$A$136:$A$159,A9,Calculation_Engine!$L$136:$L$159) -> 1130
A10: Keri Wetzel | D10: =SUMIF(Calculation_Engine!$A$136:$A$159,A10,Calculation_Engine!$L$136:$L$159) -> 1375
A11: Shaunte Osorio | D11: =SUMIF(Calculation_Engine!$A$136:$A$159,A11,Calculation_Engine!$L$136:$L$159) -> 1414
A12: Ivana Hage | D12: =SUMIF(Calculation_Engine!$A$136:$A$159,A12,Calculation_Engine!$L$136:$L$159) -> 980
A13: Paulina Mckinny | D13: =SUMIF(Calculation_Engine!$A$136:$A$159,A13,Calculation_Engine!$L$136:$L$159) -> 1007
A14: Bette Priddy | D14: =SUMIF(Calculation_Engine!$A$136:$A$159,A14,Calculation_Engine!$L$136:$L$159) -> 1232
A19: Costos Totales de los principales lugares
A20: Mulhalla Falls | B20: 7 | D20: =SUMIF(Calculation_Engine!$C$106:$K$130,Executive_Summary!B20,Calculation_Engine!$C$135:$L$159) -> 1701
A21: Cronberg Gorge | B21: 6 | D21: =SUMIF(Calculation_Engine!$C$106:$K$130,Executive_Summary!B21,Calculation_Engine!$C$135:$L$159) -> 1584
A22: Falken Woods | B22: 5 | D22: =SUMIF(Calculation_Engine!$C$106:$K$130,Executive_Summary!B22,Calculation_Engine!$C$135:$L$159) -> 1578
A26: Costos totales de transporte si empezamos en Orange Grove | D26: =SUM(Calculation_Engine!$L$200:$L$223) -> 21865

Sheet Calculation_Engine
A2: Conteo de Juegos y Ubicación por Competidor
A3: Competidora 1 | B3: Competidora 2 | C3: Lugar | D3: # de Juego para comp 1 | E3: # de Juego para comp 2 | F3: # de Lugar
A4: Gaynell Lehrman | B4: Ivana Hage | C4: Dome Rock | D4: =COUNTIF($A$4:$B4,A4) -> 1 | E4: =COUNTIF($A$4:$B4,B4) -> 1 | F4: =_xlfn.XLOOKUP(C4,Calculation_Engine!$O$78:$O$89,Raw_Data!$E$9:$E$20,0,0) -> 1
A5: Keri Wetzel | B5: Bette Priddy | C5: Orange Grove | D5: =COUNTIF($A$4:$B5,A5) -> 1 | E5: =COUNTIF($A$4:$B5,B5) -> 1 | F5: =_xlfn.XLOOKUP(C5,Calculation_Engine!$O$78:$O$89,Raw_Data!$E$9:$E$20,0,0) -> 2
A6: Meda Maddix | B6: Shavonda Spooner | C6: Lemon Field | D6: =COUNTIF($A$4:$B6,A6) -> 1 | E6: =COUNTIF($A$4:$B6,B6) -> 1 | F6: =_xlfn.XLOOKUP(C6,Calculation_Engine!$O$78:$O$89,Raw_Data!$E$9:$E$20,0,0) -> 3
A7: Shaunte Osorio | B7: Paulina Mckinny | C7: Sunken Hill | D7: =COUNTIF($A$4:$B7,A7) -> 1 | E7: =COUNTIF($A$4:$B7,B7) -> 1 | F7: =_xlfn.XLOOKUP(C7,Calculation_Engine!$O$78:$O$89,Raw_Data!$E$9:$E$20,0,0) -> 4
A8: Sulema Hyre | B8: Ute Volpe | C8: Falken Woods | D8: =COUNTIF($A$4:$B8,A8) -> 1 | E8: =COUNTIF($A$4:$B8,B8) -> 1 | F8: =_xlfn.XLOOKUP(C8,Calculation_Engine!$O$78:$O$89,Raw_Data!$E$9:$E$20,0,0) -> 5
A9: Ivelisse Ellenwood | B9: Simona Baumeister | C9: Cronberg Gorge | D9: =COUNTIF($A$4:$B9,A9) -> 1 | E9: =COUNTIF($A$4:$B9,B9) -> 1 | F9: =_xlfn.XLOOKUP(C9,Calculation_Engine!$O$78:$O$89,Raw_Data!$E$9:$E$20,0,0) -> 6
A10: Christin Gladding | B10: Tiana Munoz | C10: Mulhalla Falls | D10: =COUNTIF($A$4:$B10,A10) -> 1 | E10: =COUNTIF($A$4:$B10,B10) -> 1 | F10: =_xlfn.XLOOKUP(C10,Calculation_Engine!$O$78:$O$89,Raw_Data!$E$9:$E$20,0,0) -> 7
A11: Senaida Glanz | B11: Emmie Baugher | C11: Matier Range | D11: =COUNTIF($A$4:$B11,A11) -> 1 | E11: =COUNTIF($A$4:$B11,B11) -> 1 | F11: =_xlfn.XLOOKUP(C11,Calculation_Engine!$O$78:$O$89,Raw_Data!$E$9:$E$20,0,0) -> 8
A12: Dorthey Magruder | B12: Lashanda Pangborn | C12: Lake Guideon | D12: =COUNTIF($A$4:$B12,A12) -> 1 | E12: =COUNTIF($A$4:$B12,B12) -> 1 | F12: =_xlfn.XLOOKUP(C12,Calculation_Engine!$O$78:$O$89,Raw_Data!$E$9:$E$20,0,0) -> 9
A13: Lue Rocheleau | B13: Taisha Kauppi | C13: Red Creek | D13: =COUNTIF($A$4:$B13,A13) -> 1 | E13: =COUNTIF($A$4:$B13,B13) -> 1 | F13: =_xlfn.XLOOKUP(C13,Calculation_Engine!$O$78:$O$89,Raw_Data!$E$9:$E$20,0,0) -> 10
A14: Katharina Housman | B14: Amal Bunt | C14: Clarkson Town | D14: =COUNTIF($A$4:$B14,A14) -> 1 | E14: =COUNTIF($A$4:$B14,B14) -> 1 | F14: =_xlfn.XLOOKUP(C14,Calculation_Engine!$O$78:$O$89,Raw_Data!$E$9:$E$20,0,0) -> 11
A15: Jenniffer Berumen | B15: Marylynn Emmer | C15: Boiling Pools | D15: =COUNTIF($A$4:$B15,A15) -> 1 | E15: =COUNTIF($A$4:$B15,B15) -> 1 | F15: =_xlfn.XLOOKUP(C15,Calculation_Engine!$O$78:$O$89,Raw_Data!$E$9:$E$20,0,0) -> 12
... A70: Gaynell Lehrman | B70: Meda Maddix | C70: Mulhalla Falls | D70: =COUNTIF($A$4:$B70,A70) -> 8 | E70: =COUNTIF($A$4:$B70,B70) -> 8 | F70: =_xlfn.XLOOKUP(C70,Calculation_Engine!$O$78:$O$89,Raw_Data!$E$9:$E$20,0,0) -> 7
A76: Progresión de Competidores Por Ronda
B77: Inicio | C77: 1 | D77: 2 | E77: 3 | F77: 4 | G77: 5 | H77: 6 | I77: 7 | J77: 8 | K77: Fin | N77: Numero. | O77: Ubicaciones
A78: Gaynell Lehrman | B78: 11 | C78: =SUMIFS($F$3:$F$70,$D$3:$D$70,C$77,$A$3:$A$70,$A78)+SUMIFS($F$3:$F$70,$E$3:$E$70,C$77,$B$3:$B$70,$A78) -> 1 | D78: =SUMIFS($F$3:$F$70,$D$3:$D$70,D$77,$A$3:$A$70,$A78)+SUMIFS($F$3:$F$70,$E$3:$E$70,D$77,$B$3:$B$70,$A78) -> 1 | E78: =SUMIFS($F$3:$F$70,$D$3:$D$70,E$77,$A$3:$A$70,$A78)+SUMIFS($F$3:$F$70,$E$3:$E$70,E$77,$B$3:$B$70,$A78) -> 9 | F78: =SUMIFS($F$3:$F$70,$D$3:$D$70,F$77,$A$3:$A$70,$A78)+SUMIFS($F$3:$F$70,$E$3:$E$70,F$77,$B$3:$B$70,$A78) -> 1 | G78: =SUMIFS($F$3:$F$70,$D$3:$D$70,G$77,$A$3:$A$70,$A78)+SUMIFS($F$3:$F$70,$E$3:$E$70,G$77,$B$3:$B$70,$A78) -> 9 | H78: =SUMIFS($F$3:$F$70,$D$3:$D$70,H$77,$A$3:$A$70,$A78)+SUMIFS($F$3:$F$70,$E$3:$E$70,H$77,$B$3:$B$70,$A78) -> 1 | I78: =SUMIFS($F$3:$F$70,$D$3:$D$70,I$77,$A$3:$A$70,$A78)+SUMIFS($F$3:$F$70,$E$3:$E$70,I$77,$B$3:$B$70,$A78) -> 5 | J78: =SUMIFS($F$3:$F$70,$D$3:$D$70,J$77,$A$3:$A$70,$A78)+SUMIFS($F$3:$F$70,$E$3:$E$70,J$77,$B$3:$B$70,$A78) -> 7 | K78: 11 | N78: 1 | O78: Dome Rock
A79: Meda Maddix | B79: 11 | C79: =SUMIFS($F$3:$F$70,$D$3:$D$70,C$77,$A$3:$A$70,$A79)+SUMIFS($F$3:$F$70,$E$3:$E$70,C$77,$B$3:$B$70,$A79) -> 3 | D79: =SUMIFS($F$3:$F$70,$D$3:$D$70,D$77,$A$3:$A$70,$A79)+SUMIFS($F$3:$F$70,$E$3:$E$70,D$77,$B$3:$B$70,$A79) -> 3 | E79: =SUMIFS($F$3:$F$70,$D$3:$D$70,E$77,$A$3:$A$70,$A79)+SUMIFS($F$3:$F$70,$E$3:$E$70,E$77,$B$3:$B$70,$A79) -> 11 | F79: =SUMIFS($F$3:$F$70,$D$3:$D$70,F$77,$A$3:$A$70,$A79)+SUMIFS($F$3:$F$70,$E$3:$E$70,F$77,$B$3:$B$70,$A79) -> 3 | G79: =SUMIFS($F$3:$F$70,$D$3:$D$70,G$77,$A$3:$A$70,$A79)+SUMIFS($F$3:$F$70,$E$3:$E$70,G$77,$B$3:$B$70,$A79) -> 11 | H79: =SUMIFS($F$3:$F$70,$D$3:$D$70,H$77,$A$3:$A$70,$A79)+SUMIFS($F$3:$F$70,$E$3:$E$70,H$77,$B$3:$B$70,$A79) -> 2 | I79: =SUMIFS($F$3:$F$70,$D$3:$D$70,I$77,$A$3:$A$70,$A79)+SUMIFS($F$3:$F$70,$E$3:$E$70,I$77,$B$3:$B$70,$A79) -> 6 | J79: =SUMIFS($F$3:$F$70,$D$3:$D$70,J$77,$A$3:$A$70,$A79)+SUMIFS($F$3:$F$70,$E$3:$E$70,J$77,$B$3:$B$70,$A79) -> 7 | K79: 11 | N79: 2 | O79: Orange Grove
A80: Keri Wetzel | B80: 11 | C80: =SUMIFS($F$3:$F$70,$D$3:$D$70,C$77,$A$3:$A$70,$A80)+SUMIFS($F$3:$F$70,$E$3:$E$70,C$77,$B$3:$B$70,$A80) -> 2 | D80: =SUMIFS($F$3:$F$70,$D$3:$D$70,D$77,$A$3:$A$70,$A80)+SUMIFS($F$3:$F$70,$E$3:$E$70,D$77,$B$3:$B$70,$A80) -> 2 | E80: =SUMIFS($F$3:$F$70,$D$3:$D$70,E$77,$A$3:$A$70,$A80)+SUMIFS($F$3:$F$70,$E$3:$E$70,E$77,$B$3:$B$70,$A80) -> 10 | F80: =SUMIFS($F$3:$F$70,$D$3:$D$70,F$77,$A$3:$A$70,$A80)+SUMIFS($F$3:$F$70,$E$3:$E$70,F$77,$B$3:$B$70,$A80) -> 2 | G80: =SUMIFS($F$3:$F$70,$D$3:$D$70,G$77,$A$3:$A$70,$A80)+SUMIFS($F$3:$F$70,$E$3:$E$70,G$77,$B$3:$B$70,$A80) -> 10 | H80: =SUMIFS($F$3:$F$70,$D$3:$D$70,H$77,$A$3:$A$70,$A80)+SUMIFS($F$3:$F$70,$E$3:$E$70,H$77,$B$3:$B$70,$A80) -> 3 | I80: =SUMIFS($F$3:$F$70,$D$3:$D$70,I$77,$A$3:$A$70,$A80)+SUMIFS($F$3:$F$70,$E$3:$E$70,I$77,$B$3:$B$70,$A80) -> 6 | J80: =SUMIFS($F$3:$F$70,$D$3:$D$70,J$77,$A$3:$A$70,$A80)+SUMIFS($F$3:$F$70,$E$3:$E$70,J$77,$B$3:$B$70,$A80) -> 0 | K80: 11 | N80: 3 | O80: Lemon Field
A81: Shaunte Osorio | B81: 11 | C81: =SUMIFS($F$3:$F$70,$D$3:$D$70,C$77,$A$3:$A$70,$A81)+SUMIFS($F$3:$F$70,$E$3:$E$70,C$77,$B$3:$B$70,$A81) -> 4 | D81: =SUMIFS($F$3:$F$70,$D$3:$D$70,D$77,$A$3:$A$70,$A81)+SUMIFS($F$3:$F$70,$E$3:$E$70,D$77,$B$3:$B$70,$A81) -> 4 | E81: =SUMIFS($F$3:$F$70,$D$3:$D$70,E$77,$A$3:$A$70,$A81)+SUMIFS($F$3:$F$70,$E$3:$E$70,E$77,$B$3:$B$70,$A81) -> 12 | F81: =SUMIFS($F$3:$F$70,$D$3:$D$70,F$77,$A$3:$A$70,$A81)+SUMIFS($F$3:$F$70,$E$3:$E$70,F$77,$B$3:$B$70,$A81) -> 4 | G81: =SUMIFS($F$3:$F$70,$D$3:$D$70,G$77,$A$3:$A$70,$A81)+SUMIFS($F$3:$F$70,$E$3:$E$70,G$77,$B$3:$B$70,$A81) -> 12 | H81: =SUMIFS($F$3:$F$70,$D$3:$D$70,H$77,$A$3:$A$70,$A81)+SUMIFS($F$3:$F$70,$E$3:$E$70,H$77,$B$3:$B$70,$A81) -> 4 | I81: =SUMIFS($F$3:$F$70,$D$3:$D$70,I$77,$A$3:$A$70,$A81)+SUMIFS($F$3:$F$70,$E$3:$E$70,I$77,$B$3:$B$70,$A81) -> 5 | J81: =SUMIFS($F$3:$F$70,$D$3:$D$70,J$77,$A$3:$A$70,$A81)+SUMIFS($F$3:$F$70,$E$3:$E$70,J$77,$B$3:$B$70,$A81) -> 0 | K81: 11 | N81: 4 | O81: Sunken Hill
A82: Ivana Hage | B82: 11 | C82: =SUMIFS($F$3:$F$70,$D$3:$D$70,C$77,$A$3:$A$70,$A82)+SUMIFS($F$3:$F$70,$E$3:$E$70,C$77,$B$3:$B$70,$A82) -> 1 | D82: =SUMIFS($F$3:$F$70,$D$3:$D$70,D$77,$A$3:$A$70,$A82)+SUMIFS($F$3:$F$70,$E$3:$E$70,D$77,$B$3:$B$70,$A82) -> 5 | E82: =SUMIFS($F$3:$F$70,$D$3:$D$70,E$77,$A$3:$A$70,$A82)+SUMIFS($F$3:$F$70,$E$3:$E$70,E$77,$B$3:$B$70,$A82) -> 5 | F82: =SUMIFS($F$3:$F$70,$D$3:$D$70,F$77,$A$3:$A$70,$A82)+SUMIFS($F$3:$F$70,$E$3:$E$70,F$77,$B$3:$B$70,$A82) -> 1 | G82: =SUMIFS($F$3:$F$70,$D$3:$D$70,G$77,$A$3:$A$70,$A82)+SUMIFS($F$3:$F$70,$E$3:$E$70,G$77,$B$3:$B$70,$A82) -> 5 | H82: =SUMIFS($F$3:$F$70,$D$3:$D$70,H$77,$A$3:$A$70,$A82)+SUMIFS($F$3:$F$70,$E$3:$E$70,H$77,$B$3:$B$70,$A82) -> 4 | I82: =SUMIFS($F$3:$F$70,$D$3:$D$70,I$77,$A$3:$A$70,$A82)+SUMIFS($F$3:$F$70,$E$3:$E$70,I$77,$B$3:$B$70,$A82) -> 0 | J82: =SUMIFS($F$3:$F$70,$D$3:$D$70,J$77,$A$3:$A$70,$A82)+SUMIFS($F$3:$F$70,$E$3:$E$70,J$77,$B$3:$B$70,$A82) -> 0 | K82: 11 | N82: 5 | O82: Falken Woods
A83: Shavonda Spooner | B83: 11 | C83: =SUMIFS($F$3:$F$70,$D$3:$D$70,C$77,$A$3:$A$70,$A83)+SUMIFS($F$3:$F$70,$E$3:$E$70,C$77,$B$3:$B$70,$A83) -> 3 | D83: =SUMIFS($F$3:$F$70,$D$3:$D$70,D$77,$A$3:$A$70,$A83)+SUMIFS($F$3:$F$70,$E$3:$E$70,D$77,$B$3:$B$70,$A83) -> 7 | E83: =SUMIFS($F$3:$F$70,$D$3:$D$70,E$77,$A$3:$A$70,$A83)+SUMIFS($F$3:$F$70,$E$3:$E$70,E$77,$B$3:$B$70,$A83) -> 7 | F83: =SUMIFS($F$3:$F$70,$D$3:$D$70,F$77,$A$3:$A$70,$A83)+SUMIFS($F$3:$F$70,$E$3:$E$70,F$77,$B$3:$B$70,$A83) -> 3 | G83: =SUMIFS($F$3:$F$70,$D$3:$D$70,G$77,$A$3:$A$70,$A83)+SUMIFS($F$3:$F$70,$E$3:$E$70,G$77,$B$3:$B$70,$A83) -> 7 | H83: =SUMIFS($F$3:$F$70,$D$3:$D$70,H$77,$A$3:$A$70,$A83)+SUMIFS($F$3:$F$70,$E$3:$E$70,H$77,$B$3:$B$70,$A83) -> 3 | I83: =SUMIFS($F$3:$F$70,$D$3:$D$70,I$77,$A$3:$A$70,$A83)+SUMIFS($F$3:$F$70,$E$3:$E$70,I$77,$B$3:$B$70,$A83) -> 0 | J83: =SUMIFS($F$3:$F$70,$D$3:$D$70,J$77,$A$3:$A$70,$A83)+SUMIFS($F$3:$F$70,$E$3:$E$70,J$77,$B$3:$B$70,$A83) -> 0 | K83: 11 | N83: 6 | O83: Cronberg Gorge
A84: Bette Priddy | B84: 11 | C84: =SUMIFS($F$3:$F$70,$D$3:$D$70,C$77,$A$3:$A$70,$A84)+SUMIFS($F$3:$F$70,$E$3:$E$70,C$77,$B$3:$B$70,$A84) -> 2 | D84: =SUMIFS($F$3:$F$70,$D$3:$D$70,D$77,$A$3:$A$70,$A84)+SUMIFS($F$3:$F$70,$E$3:$E$70,D$77,$B$3:$B$70,$A84) -> 6 | E84: =SUMIFS($F$3:$F$70,$D$3:$D$70,E$77,$A$3:$A$70,$A84)+SUMIFS($F$3:$F$70,$E$3:$E$70,E$77,$B$3:$B$70,$A84) -> 6 | F84: =SUMIFS($F$3:$F$70,$D$3:$D$70,F$77,$A$3:$A$70,$A84)+SUMIFS($F$3:$F$70,$E$3:$E$70,F$77,$B$3:$B$70,$A84) -> 2 | G84: =SUMIFS($F$3:$F$70,$D$3:$D$70,G$77,$A$3:$A$70,$A84)+SUMIFS($F$3:$F$70,$E$3:$E$70,G$77,$B$3:$B$70,$A84) -> 6 | H84: =SUMIFS($F$3:$F$70,$D$3:$D$70,H$77,$A$3:$A$70,$A84)+SUMIFS($F$3:$F$70,$E$3:$E$70,H$77,$B$3:$B$70,$A84) -> 2 | I84: =SUMIFS($F$3:$F$70,$D$3:$D$70,I$77,$A$3:$A$70,$A84)+SUMIFS($F$3:$F$70,$E$3:$E$70,I$77,$B$3:$B$70,$A84) -> 0 | J84: =SUMIFS($F$3:$F$70,$D$3:$D$70,J$77,$A$3:$A$70,$A84)+SUMIFS($F$3:$F$70,$E$3:$E$70,J$77,$B$3:$B$70,$A84) -> 0 | K84: 11 | N84: 7 | O84: Mulhalla Falls
A85: Paulina Mckinny | B85: 11 | C85: =SUMIFS($F$3:$F$70,$D$3:$D$70,C$77,$A$3:$A$70,$A85)+SUMIFS($F$3:$F$70,$E$3:$E$70,C$77,$B$3:$B$70,$A85) -> 4 | D85: =SUMIFS($F$3:$F$70,$D$3:$D$70,D$77,$A$3:$A$70,$A85)+SUMIFS($F$3:$F$70,$E$3:$E$70,D$77,$B$3:$B$70,$A85) -> 8 | E85: =SUMIFS($F$3:$F$70,$D$3:$D$70,E$77,$A$3:$A$70,$A85)+SUMIFS($F$3:$F$70,$E$3:$E$70,E$77,$B$3:$B$70,$A85) -> 8 | F85: =SUMIFS($F$3:$F$70,$D$3:$D$70,F$77,$A$3:$A$70,$A85)+SUMIFS($F$3:$F$70,$E$3:$E$70,F$77,$B$3:$B$70,$A85) -> 4 | G85: =SUMIFS($F$3:$F$70,$D$3:$D$70,G$77,$A$3:$A$70,$A85)+SUMIFS($F$3:$F$70,$E$3:$E$70,G$77,$B$3:$B$70,$A85) -> 8 | H85: =SUMIFS($F$3:$F$70,$D$3:$D$70,H$77,$A$3:$A$70,$A85)+SUMIFS($F$3:$F$70,$E$3:$E$70,H$77,$B$3:$B$70,$A85) -> 1 | I85: =SUMIFS($F$3:$F$70,$D$3:$D$70,I$77,$A$3:$A$70,$A85)+SUMIFS($F$3:$F$70,$E$3:$E$70,I$77,$B$3:$B$70,$A85) -> 0 | J85: =SUMIFS($F$3:$F$70,$D$3:$D$70,J$77,$A$3:$A$70,$A85)+SUMIFS($F$3:$F$70,$E$3:$E$70,J$77,$B$3:$B$70,$A85) -> 0 | K85: 11 | N85: 8 | O85: Matier Range
A86: Sulema Hyre | B86: 11 | C86: =SUMIFS($F$3:$F$70,$D$3:$D$70,C$77,$A$3:$A$70,$A86)+SUMIFS($F$3:$F$70,$E$3:$E$70,C$77,$B$3:$B$70,$A86) -> 5 | D86: =SUMIFS($F$3:$F$70,$D$3:$D$70,D$77,$A$3:$A$70,$A86)+SUMIFS($F$3:$F$70,$E$3:$E$70,D$77,$B$3:$B$70,$A86) -> 1 | E86: =SUMIFS($F$3:$F$70,$D$3:$D$70,E$77,$A$3:$A$70,$A86)+SUMIFS($F$3:$F$70,$E$3:$E$70,E$77,$B$3:$B$70,$A86) -> 9 | F86: =SUMIFS($F$3:$F$70,$D$3:$D$70,F$77,$A$3:$A$70,$A86)+SUMIFS($F$3:$F$70,$E$3:$E$70,F$77,$B$3:$B$70,$A86) -> 9 | G86: =SUMIFS($F$3:$F$70,$D$3:$D$70,G$77,$A$3:$A$70,$A86)+SUMIFS($F$3:$F$70,$E$3:$E$70,G$77,$B$3:$B$70,$A86) -> 5 | H86: =SUMIFS($F$3:$F$70,$D$3:$D$70,H$77,$A$3:$A$70,$A86)+SUMIFS($F$3:$F$70,$E$3:$E$70,H$77,$B$3:$B$70,$A86) -> 0 | I86: =SUMIFS($F$3:$F$70,$D$3:$D$70,I$77,$A$3:$A$70,$A86)+SUMIFS($F$3:$F$70,$E$3:$E$70,I$77,$B$3:$B$70,$A86) -> 0 | J86: =SUMIFS($F$3:$F$70,$D$3:$D$70,J$77,$A$3:$A$70,$A86)+SUMIFS($F$3:$F$70,$E$3:$E$70,J$77,$B$3:$B$70,$A86) -> 0 | K86: 11 | N86: 9 | O86: Lake Guideon
A87: Christin Gladding | B87: 11 | C87: =SUMIFS($F$3:$F$70,$D$3:$D$70,C$77,$A$3:$A$70,$A87)+SUMIFS($F$3:$F$70,$E$3:$E$70,C$77,$B$3:$B$70,$A87) -> 7 | D87: =SUMIFS($F$3:$F$70,$D$3:$D$70,D$77,$A$3:$A$70,$A87)+SUMIFS($F$3:$F$70,$E$3:$E$70,D$77,$B$3:$B$70,$A87) -> 3 | E87: =SUMIFS($F$3:$F$70,$D$3:$D$70,E$77,$A$3:$A$70,$A87)+SUMIFS($F$3:$F$70,$E$3:$E$70,E$77,$B$3:$B$70,$A87) -> 11 | F87: =SUMIFS($F$3:$F$70,$D$3:$D$70,F$77,$A$3:$A$70,$A87)+SUMIFS($F$3:$F$70,$E$3:$E$70,F$77,$B$3:$B$70,$A87) -> 11 | G87: =SUMIFS($F$3:$F$70,$D$3:$D$70,G$77,$A$3:$A$70,$A87)+SUMIFS($F$3:$F$70,$E$3:$E$70,G$77,$B$3:$B$70,$A87) -> 7 | H87: =SUMIFS($F$3:$F$70,$D$3:$D$70,H$77,$A$3:$A$70,$A87)+SUMIFS($F$3:$F$70,$E$3:$E$70,H$77,$B$3:$B$70,$A87) -> 0 | I87: =SUMIFS($F$3:$F$70,$D$3:$D$70,I$77,$A$3:$A$70,$A87)+SUMIFS($F$3:$F$70,$E$3:$E$70,I$77,$B$3:$B$70,$A87) -> 0 | J87: =SUMIFS($F$3:$F$70,$D$3:$D$70,J$77,$A$3:$A$70,$A87)+SUMIFS($F$3:$F$70,$E$3:$E$70,J$77,$B$3:$B$70,$A87) -> 0 | K87: 11 | N87: 10 | O87: Red Creek
A88: Ivelisse Ellenwood | B88: 11 | C88: =SUMIFS($F$3:$F$70,$D$3:$D$70,C$77,$A$3:$A$70,$A88)+SUMIFS($F$3:$F$70,$E$3:$E$70,C$77,$B$3:$B$70,$A88) -> 6 | D88: =SUMIFS($F$3:$F$70,$D$3:$D$70,D$77,$A$3:$A$70,$A88)+SUMIFS($F$3:$F$70,$E$3:$E$70,D$77,$B$3:$B$70,$A88) -> 2 | E88: =SUMIFS($F$3:$F$70,$D$3:$D$70,E$77,$A$3:$A$70,$A88)+SUMIFS($F$3:$F$70,$E$3:$E$70,E$77,$B$3:$B$70,$A88) -> 10 | F88: =SUMIFS($F$3:$F$70,$D$3:$D$70,F$77,$A$3:$A$70,$A88)+SUMIFS($F$3:$F$70,$E$3:$E$70,F$77,$B$3:$B$70,$A88) -> 10 | G88: =SUMIFS($F$3:$F$70,$D$3:$D$70,G$77,$A$3:$A$70,$A88)+SUMIFS($F$3:$F$70,$E$3:$E$70,G$77,$B$3:$B$70,$A88) -> 6 | H88: =SUMIFS($F$3:$F$70,$D$3:$D$70,H$77,$A$3:$A$70,$A88)+SUMIFS($F$3:$F$70,$E$3:$E$70,H$77,$B$3:$B$70,$A88) -> 0 | I88: =SUMIFS($F$3:$F$70,$D$3:$D$70,I$77,$A$3:$A$70,$A88)+SUMIFS($F$3:$F$70,$E$3:$E$70,I$77,$B$3:$B$70,$A88) -> 0 | J88: =SUMIFS($F$3:$F$70,$D$3:$D$70,J$77,$A$3:$A$70,$A88)+SUMIFS($F$3:$F$70,$E$3:$E$70,J$77,$B$3:$B$70,$A88) -> 0 | K88: 11 | N88: 11 | O88: Clarkson Town
A89: Senaida Glanz | B89: 11 | C89: =SUMIFS($F$3:$F$70,$D$3:$D$70,C$77,$A$3:$A$70,$A89)+SUMIFS($F$3:$F$70,$E$3:$E$70,C$77,$B$3:$B$70,$A89) -> 8 | D89: =SUMIFS($F$3:$F$70,$D$3:$D$70,D$77,$A$3:$A$70,$A89)+SUMIFS($F$3:$F$70,$E$3:$E$70,D$77,$B$3:$B$70,$A89) -> 4 | E89: =SUMIFS($F$3:$F$70,$D$3:$D$70,E$77,$A$3:$A$70,$A89)+SUMIFS($F$3:$F$70,$E$3:$E$70,E$77,$B$3:$B$70,$A89) -> 12 | F89: =SUMIFS($F$3:$F$70,$D$3:$D$70,F$77,$A$3:$A$70,$A89)+SUMIFS($F$3:$F$70,$E$3:$E$70,F$77,$B$3:$B$70,$A89) -> 12 | G89: =SUMIFS($F$3:$F$70,$D$3:$D$70,G$77,$A$3:$A$70,$A89)+SUMIFS($F$3:$F$70,$E$3:$E$70,G$77,$B$3:$B$70,$A89) -> 8 | H89: =SUMIFS($F$3:$F$70,$D$3:$D$70,H$77,$A$3:$A$70,$A89)+SUMIFS($F$3:$F$70,$E$3:$E$70,H$77,$B$3:$B$70,$A89) -> 0 | I89: =SUMIFS($F$3:$F$70,$D$3:$D$70,I$77,$A$3:$A$70,$A89)+SUMIFS($F$3:$F$70,$E$3:$E$70,I$77,$B$3:$B$70,$A89) -> 0 | J89: =SUMIFS($F$3:$F$70,$D$3:$D$70,J$77,$A$3:$A$70,$A89)+SUMIFS($F$3:$F$70,$E$3:$E$70,J$77,$B$3:$B$70,$A89) -> 0 | K89: 11 | N89: 12 | O89: Boiling Pools
A90: Ute Volpe | B90: 11 | C90: =SUMIFS($F$3:$F$70,$D$3:$D$70,C$77,$A$3:$A$70,$A90)+SUMIFS($F$3:$F$70,$E$3:$E$70,C$77,$B$3:$B$70,$A90) -> 5 | D90: =SUMIFS($F$3:$F$70,$D$3:$D$70,D$77,$A$3:$A$70,$A90)+SUMIFS($F$3:$F$70,$E$3:$E$70,D$77,$B$3:$B$70,$A90) -> 5 | E90: =SUMIFS($F$3:$F$70,$D$3:$D$70,E$77,$A$3:$A$70,$A90)+SUMIFS($F$3:$F$70,$E$3:$E$70,E$77,$B$3:$B$70,$A90) -> 1 | F90: =SUMIFS($F$3:$F$70,$D$3:$D$70,F$77,$A$3:$A$70,$A90)+SUMIFS($F$3:$F$70,$E$3:$E$70,F$77,$B$3:$B$70,$A90) -> 9 | G90: =SUMIFS($F$3:$F$70,$D$3:$D$70,G$77,$A$3:$A$70,$A90)+SUMIFS($F$3:$F$70,$E$3:$E$70,G$77,$B$3:$B$70,$A90) -> 5 | H90: =SUMIFS($F$3:$F$70,$D$3:$D$70,H$77,$A$3:$A$70,$A90)+SUMIFS($F$3:$F$70,$E$3:$E$70,H$77,$B$3:$B$70,$A90) -> 0 | I90: =SUMIFS($F$3:$F$70,$D$3:$D$70,I$77,$A$3:$A$70,$A90)+SUMIFS($F$3:$F$70,$E$3:$E$70,I$77,$B$3:$B$70,$A90) -> 0 | J90: =SUMIFS($F$3:$F$70,$D$3:$D$70,J$77,$A$3:$A$70,$A90)+SUMIFS($F$3:$F$70,$E$3:$E$70,J$77,$B$3:$B$70,$A90) -> 0 | K90: 11
A91: Tiana Munoz | B91: 11 | C91: =SUMIFS($F$3:$F$70,$D$3:$D$70,C$77,$A$3:$A$70,$A91)+SUMIFS($F$3:$F$70,$E$3:$E$70,C$77,$B$3:$B$70,$A91) -> 7 | D91: =SUMIFS($F$3:$F$70,$D$3:$D$70,D$77,$A$3:$A$70,$A91)+SUMIFS($F$3:$F$70,$E$3:$E$70,D$77,$B$3:$B$70,$A91) -> 7 | E91: =SUMIFS($F$3:$F$70,$D$3:$D$70,E$77,$A$3:$A$70,$A91)+SUMIFS($F$3:$F$70,$E$3:$E$70,E$77,$B$3:$B$70,$A91) -> 3 | F91: =SUMIFS($F$3:$F$70,$D$3:$D$70,F$77,$A$3:$A$70,$A91)+SUMIFS($F$3:$F$70,$E$3:$E$70,F$77,$B$3:$B$70,$A91) -> 11 | G91: =SUMIFS($F$3:$F$70,$D$3:$D$70,G$77,$A$3:$A$70,$A91)+SUMIFS($F$3:$F$70,$E$3:$E$70,G$77,$B$3:$B$70,$A91) -> 7 | H91: =SUMIFS($F$3:$F$70,$D$3:$D$70,H$77,$A$3:$A$70,$A91)+SUMIFS($F$3:$F$70,$E$3:$E$70,H$77,$B$3:$B$70,$A91) -> 0 | I91: =SUMIFS($F$3:$F$70,$D$3:$D$70,I$77,$A$3:$A$70,$A91)+SUMIFS($F$3:$F$70,$E$3:$E$70,I$77,$B$3:$B$70,$A91) -> 0 | J91: =SUMIFS($F$3:$F$70,$D$3:$D$70,J$77,$A$3:$A$70,$A91)+SUMIFS($F$3:$F$70,$E$3:$E$70,J$77,$B$3:$B$70,$A91) -> 0 | K91: 11
A92: Simona Baumeister | B92: 11 | C92: =SUMIFS($F$3:$F$70,$D$3:$D$70,C$77,$A$3:$A$70,$A92)+SUMIFS($F$3:$F$70,$E$3:$E$70,C$77,$B$3:$B$70,$A92) -> 6 | D92: =SUMIFS($F$3:$F$70,$D$3:$D$70,D$77,$A$3:$A$70,$A92)+SUMIFS($F$3:$F$70,$E$3:$E$70,D$77,$B$3:$B$70,$A92) -> 6 | E92: =SUMIFS($F$3:$F$70,$D$3:$D$70,E$77,$A$3:$A$70,$A92)+SUMIFS($F$3:$F$70,$E$3:$E$70,E$77,$B$3:$B$70,$A92) -> 2 | F92: =SUMIFS($F$3:$F$70,$D$3:$D$70,F$77,$A$3:$A$70,$A92)+SUMIFS($F$3:$F$70,$E$3:$E$70,F$77,$B$3:$B$70,$A92) -> 10 | G92: =SUMIFS($F$3:$F$70,$D$3:$D$70,G$77,$A$3:$A$70,$A92)+SUMIFS($F$3:$F$70,$E$3:$E$70,G$77,$B$3:$B$70,$A92) -> 6 | H92: =SUMIFS($F$3:$F$70,$D$3:$D$70,H$77,$A$3:$A$70,$A92)+SUMIFS($F$3:$F$70,$E$3:$E$70,H$77,$B$3:$B$70,$A92) -> 0 | I92: =SUMIFS($F$3:$F$70,$D$3:$D$70,I$77,$A$3:$A$70,$A92)+SUMIFS($F$3:$F$70,$E$3:$E$70,I$77,$B$3:$B$70,$A92) -> 0 | J92: =SUMIFS($F$3:$F$70,$D$3:$D$70,J$77,$A$3:$A$70,$A92)+SUMIFS($F$3:$F$70,$E$3:$E$70,J$77,$B$3:$B$70,$A92) -> 0 | K92: 11
A93: Emmie Baugher | B93: 11 | C93: =SUMIFS($F$3:$F$70,$D$3:$D$70,C$77,$A$3:$A$70,$A93)+SUMIFS($F$3:$F$70,$E$3:$E$70,C$77,$B$3:$B$70,$A93) -> 8 | D93: =SUMIFS($F$3:$F$70,$D$3:$D$70,D$77,$A$3:$A$70,$A93)+SUMIFS($F$3:$F$70,$E$3:$E$70,D$77,$B$3:$B$70,$A93) -> 8 | E93: =SUMIFS($F$3:$F$70,$D$3:$D$70,E$77,$A$3:$A$70,$A93)+SUMIFS($F$3:$F$70,$E$3:$E$70,E$77,$B$3:$B$70,$A93) -> 4 | F93: =SUMIFS($F$3:$F$70,$D$3:$D$70,F$77,$A$3:$A$70,$A93)+SUMIFS($F$3:$F$70,$E$3:$E$70,F$77,$B$3:$B$70,$A93) -> 12 | G93: =SUMIFS($F$3:$F$70,$D$3:$D$70,G$77,$A$3:$A$70,$A93)+SUMIFS($F$3:$F$70,$E$3:$E$70,G$77,$B$3:$B$70,$A93) -> 8 | H93: =SUMIFS($F$3:$F$70,$D$3:$D$70,H$77,$A$3:$A$70,$A93)+SUMIFS($F$3:$F$70,$E$3:$E$70,H$77,$B$3:$B$70,$A93) -> 0 | I93: =SUMIFS($F$3:$F$70,$D$3:$D$70,I$77,$A$3:$A$70,$A93)+SUMIFS($F$3:$F$70,$E$3:$E$70,I$77,$B$3:$B$70,$A93) -> 0 | J93: =SUMIFS($F$3:$F$70,$D$3:$D$70,J$77,$A$3:$A$70,$A93)+SUMIFS($F$3:$F$70,$E$3:$E$70,J$77,$B$3:$B$70,$A93) -> 0 | K93: 11
A94: Dorthey Magruder | B94: 11 | C94: =SUMIFS($F$3:$F$70,$D$3:$D$70,C$77,$A$3:$A$70,$A94)+SUMIFS($F$3:$F$70,$E$3:$E$70,C$77,$B$3:$B$70,$A94) -> 9 | D94: =SUMIFS($F$3:$F$70,$D$3:$D$70,D$77,$A$3:$A$70,$A94)+SUMIFS($F$3:$F$70,$E$3:$E$70,D$77,$B$3:$B$70,$A94) -> 9 | E94: =SUMIFS($F$3:$F$70,$D$3:$D$70,E$77,$A$3:$A$70,$A94)+SUMIFS($F$3:$F$70,$E$3:$E$70,E$77,$B$3:$B$70,$A94) -> 5 | F94: =SUMIFS($F$3:$F$70,$D$3:$D$70,F$77,$A$3:$A$70,$A94)+SUMIFS($F$3:$F$70,$E$3:$E$70,F$77,$B$3:$B$70,$A94) -> 5 | G94: =SUMIFS($F$3:$F$70,$D$3:$D$70,G$77,$A$3:$A$70,$A94)+SUMIFS($F$3:$F$70,$E$3:$E$70,G$77,$B$3:$B$70,$A94) -> 1 | H94: =SUMIFS($F$3:$F$70,$D$3:$D$70,H$77,$A$3:$A$70,$A94)+SUMIFS($F$3:$F$70,$E$3:$E$70,H$77,$B$3:$B$70,$A94) -> 0 | I94: =SUMIFS($F$3:$F$70,$D$3:$D$70,I$77,$A$3:$A$70,$A94)+SUMIFS($F$3:$F$70,$E$3:$E$70,I$77,$B$3:$B$70,$A94) -> 0 | J94: =SUMIFS($F$3:$F$70,$D$3:$D$70,J$77,$A$3:$A$70,$A94)+SUMIFS($F$3:$F$70,$E$3:$E$70,J$77,$B$3:$B$70,$A94) -> 0 | K94: 11
A95: Katharina Housman | B95: 11 | C95: =SUMIFS($F$3:$F$70,$D$3:$D$70,C$77,$A$3:$A$70,$A95)+SUMIFS($F$3:$F$70,$E$3:$E$70,C$77,$B$3:$B$70,$A95) -> 11 | D95: =SUMIFS($F$3:$F$70,$D$3:$D$70,D$77,$A$3:$A$70,$A95)+SUMIFS($F$3:$F$70,$E$3:$E$70,D$77,$B$3:$B$70,$A95) -> 11 | E95: =SUMIFS($F$3:$F$70,$D$3:$D$70,E$77,$A$3:$A$70,$A95)+SUMIFS($F$3:$F$70,$E$3:$E$70,E$77,$B$3:$B$70,$A95) -> 7 | F95: =SUMIFS($F$3:$F$70,$D$3:$D$70,F$77,$A$3:$A$70,$A95)+SUMIFS($F$3:$F$70,$E$3:$E$70,F$77,$B$3:$B$70,$A95) -> 7 | G95: =SUMIFS($F$3:$F$70,$D$3:$D$70,G$77,$A$3:$A$70,$A95)+SUMIFS($F$3:$F$70,$E$3:$E$70,G$77,$B$3:$B$70,$A95) -> 3 | H95: =SUMIFS($F$3:$F$70,$D$3:$D$70,H$77,$A$3:$A$70,$A95)+SUMIFS($F$3:$F$70,$E$3:$E$70,H$77,$B$3:$B$70,$A95) -> 0 | I95: =SUMIFS($F$3:$F$70,$D$3:$D$70,I$77,$A$3:$A$70,$A95)+SUMIFS($F$3:$F$70,$E$3:$E$70,I$77,$B$3:$B$70,$A95) -> 0 | J95: =SUMIFS($F$3:$F$70,$D$3:$D$70,J$77,$A$3:$A$70,$A95)+SUMIFS($F$3:$F$70,$E$3:$E$70,J$77,$B$3:$B$70,$A95) -> 0 | K95: 11
A96: Lue Rocheleau | B96: 11 | C96: =SUMIFS($F$3:$F$70,$D$3:$D$70,C$77,$A$3:$A$70,$A96)+SUMIFS($F$3:$F$70,$E$3:$E$70,C$77,$B$3:$B$70,$A96) -> 10 | D96: =SUMIFS($F$3:$F$70,$D$3:$D$70,D$77,$A$3:$A$70,$A96)+SUMIFS($F$3:$F$70,$E$3:$E$70,D$77,$B$3:$B$70,$A96) -> 10 | E96: =SUMIFS($F$3:$F$70,$D$3:$D$70,E$77,$A$3:$A$70,$A96)+SUMIFS($F$3:$F$70,$E$3:$E$70,E$77,$B$3:$B$70,$A96) -> 6 | F96: =SUMIFS($F$3:$F$70,$D$3:$D$70,F$77,$A$3:$A$70,$A96)+SUMIFS($F$3:$F$70,$E$3:$E$70,F$77,$B$3:$B$70,$A96) -> 6 | G96: =SUMIFS($F$3:$F$70,$D$3:$D$70,G$77,$A$3:$A$70,$A96)+SUMIFS($F$3:$F$70,$E$3:$E$70,G$77,$B$3:$B$70,$A96) -> 2 | H96: =SUMIFS($F$3:$F$70,$D$3:$D$70,H$77,$A$3:$A$70,$A96)+SUMIFS($F$3:$F$70,$E$3:$E$70,H$77,$B$3:$B$70,$A96) -> 0 | I96: =SUMIFS($F$3:$F$70,$D$3:$D$70,I$77,$A$3:$A$70,$A96)+SUMIFS($F$3:$F$70,$E$3:$E$70,I$77,$B$3:$B$70,$A96) -> 0 | J96: =SUMIFS($F$3:$F$70,$D$3:$D$70,J$77,$A$3:$A$70,$A96)+SUMIFS($F$3:$F$70,$E$3:$E$70,J$77,$B$3:$B$70,$A96) -> 0 | K96: 11
A97: Jenniffer Berumen | B97: 11 | C97: =SUMIFS($F$3:$F$70,$D$3:$D$70,C$77,$A$3:$A$70,$A97)+SUMIFS($F$3:$F$70,$E$3:$E$70,C$77,$B$3:$B$70,$A97) -> 12 | D97: =SUMIFS($F$3:$F$70,$D$3:$D$70,D$77,$A$3:$A$70,$A97)+SUMIFS($F$3:$F$70,$E$3:$E$70,D$77,$B$3:$B$70,$A97) -> 12 | E97: =SUMIFS($F$3:$F$70,$D$3:$D$70,E$77,$A$3:$A$70,$A97)+SUMIFS($F$3:$F$70,$E$3:$E$70,E$77,$B$3:$B$70,$A97) -> 8 | F97: =SUMIFS($F$3:$F$70,$D$3:$D$70,F$77,$A$3:$A$70,$A97)+SUMIFS($F$3:$F$70,$E$3:$E$70,F$77,$B$3:$B$70,$A97) -> 8 | G97: =SUMIFS($F$3:$F$70,$D$3:$D$70,G$77,$A$3:$A$70,$A97)+SUMIFS($F$3:$F$70,$E$3:$E$70,G$77,$B$3:$B$70,$A97) -> 4 | H97: =SUMIFS($F$3:$F$70,$D$3:$D$70,H$77,$A$3:$A$70,$A97)+SUMIFS($F$3:$F$70,$E$3:$E$70,H$77,$B$3:$B$70,$A97) -> 0 | I97: =SUMIFS($F$3:$F$70,$D$3:$D$70,I$77,$A$3:$A$70,$A97)+SUMIFS($F$3:$F$70,$E$3:$E$70,I$77,$B$3:$B$70,$A97) -> 0 | J97: =SUMIFS($F$3:$F$70,$D$3:$D$70,J$77,$A$3:$A$70,$A97)+SUMIFS($F$3:$F$70,$E$3:$E$70,J$77,$B$3:$B$70,$A97) -> 0 | K97: 11
A98: Lashanda Pangborn | B98: 11 | C98: =SUMIFS($F$3:$F$70,$D$3:$D$70,C$77,$A$3:$A$70,$A98)+SUMIFS($F$3:$F$70,$E$3:$E$70,C$77,$B$3:$B$70,$A98) -> 9 | D98: =SUMIFS($F$3:$F$70,$D$3:$D$70,D$77,$A$3:$A$70,$A98)+SUMIFS($F$3:$F$70,$E$3:$E$70,D$77,$B$3:$B$70,$A98) -> 1 | E98: =SUMIFS($F$3:$F$70,$D$3:$D$70,E$77,$A$3:$A$70,$A98)+SUMIFS($F$3:$F$70,$E$3:$E$70,E$77,$B$3:$B$70,$A98) -> 1 | F98: =SUMIFS($F$3:$F$70,$D$3:$D$70,F$77,$A$3:$A$70,$A98)+SUMIFS($F$3:$F$70,$E$3:$E$70,F$77,$B$3:$B$70,$A98) -> 9 | G98: =SUMIFS($F$3:$F$70,$D$3:$D$70,G$77,$A$3:$A$70,$A98)+SUMIFS($F$3:$F$70,$E$3:$E$70,G$77,$B$3:$B$70,$A98) -> 9 | H98: =SUMIFS($F$3:$F$70,$D$3:$D$70,H$77,$A$3:$A$70,$A98)+SUMIFS($F$3:$F$70,$E$3:$E$70,H$77,$B$3:$B$70,$A98) -> 0 | I98: =SUMIFS($F$3:$F$70,$D$3:$D$70,I$77,$A$3:$A$70,$A98)+SUMIFS($F$3:$F$70,$E$3:$E$70,I$77,$B$3:$B$70,$A98) -> 0 | J98: =SUMIFS($F$3:$F$70,$D$3:$D$70,J$77,$A$3:$A$70,$A98)+SUMIFS($F$3:$F$70,$E$3:$E$70,J$77,$B$3:$B$70,$A98) -> 0 | K98: 11
A99: Amal Bunt | B99: 11 | C99: =SUMIFS($F$3:$F$70,$D$3:$D$70,C$77,$A$3:$A$70,$A99)+SUMIFS($F$3:$F$70,$E$3:$E$70,C$77,$B$3:$B$70,$A99) -> 11 | D99: =SUMIFS($F$3:$F$70,$D$3:$D$70,D$77,$A$3:$A$70,$A99)+SUMIFS($F$3:$F$70,$E$3:$E$70,D$77,$B$3:$B$70,$A99) -> 3 | E99: =SUMIFS($F$3:$F$70,$D$3:$D$70,E$77,$A$3:$A$70,$A99)+SUMIFS($F$3:$F$70,$E$3:$E$70,E$77,$B$3:$B$70,$A99) -> 3 | F99: =SUMIFS($F$3:$F$70,$D$3:$D$70,F$77,$A$3:$A$70,$A99)+SUMIFS($F$3:$F$70,$E$3:$E$70,F$77,$B$3:$B$70,$A99) -> 11 | G99: =SUMIFS($F$3:$F$70,$D$3:$D$70,G$77,$A$3:$A$70,$A99)+SUMIFS($F$3:$F$70,$E$3:$E$70,G$77,$B$3:$B$70,$A99) -> 11 | H99: =SUMIFS($F$3:$F$70,$D$3:$D$70,H$77,$A$3:$A$70,$A99)+SUMIFS($F$3:$F$70,$E$3:$E$70,H$77,$B$3:$B$70,$A99) -> 0 | I99: =SUMIFS($F$3:$F$70,$D$3:$D$70,I$77,$A$3:$A$70,$A99)+SUMIFS($F$3:$F$70,$E$3:$E$70,I$77,$B$3:$B$70,$A99) -> 0 | J99: =SUMIFS($F$3:$F$70,$D$3:$D$70,J$77,$A$3:$A$70,$A99)+SUMIFS($F$3:$F$70,$E$3:$E$70,J$77,$B$3:$B$70,$A99) -> 0 | K99: 11
A100: Taisha Kauppi | B100: 11 | C100: =SUMIFS($F$3:$F$70,$D$3:$D$70,C$77,$A$3:$A$70,$A100)+SUMIFS($F$3:$F$70,$E$3:$E$70,C$77,$B$3:$B$70,$A100) -> 10 | D100: =SUMIFS($F$3:$F$70,$D$3:$D$70,D$77,$A$3:$A$70,$A100)+SUMIFS($F$3:$F$70,$E$3:$E$70,D$77,$B$3:$B$70,$A100) -> 2 | E100: =SUMIFS($F$3:$F$70,$D$3:$D$70,E$77,$A$3:$A$70,$A100)+SUMIFS($F$3:$F$70,$E$3:$E$70,E$77,$B$3:$B$70,$A100) -> 2 | F100: =SUMIFS($F$3:$F$70,$D$3:$D$70,F$77,$A$3:$A$70,$A100)+SUMIFS($F$3:$F$70,$E$3:$E$70,F$77,$B$3:$B$70,$A100) -> 10 | G100: =SUMIFS($F$3:$F$70,$D$3:$D$70,G$77,$A$3:$A$70,$A100)+SUMIFS($F$3:$F$70,$E$3:$E$70,G$77,$B$3:$B$70,$A100) -> 10 | H100: =SUMIFS($F$3:$F$70,$D$3:$D$70,H$77,$A$3:$A$70,$A100)+SUMIFS($F$3:$F$70,$E$3:$E$70,H$77,$B$3:$B$70,$A100) -> 0 | I100: =SUMIFS($F$3:$F$70,$D$3:$D$70,I$77,$A$3:$A$70,$A100)+SUMIFS($F$3:$F$70,$E$3:$E$70,I$77,$B$3:$B$70,$A100) -> 0 | J100: =SUMIFS($F$3:$F$70,$D$3:$D$70,J$77,$A$3:$A$70,$A100)+SUMIFS($F$3:$F$70,$E$3:$E$70,J$77,$B$3:$B$70,$A100) -> 0 | K100: 11
...

Sheet Raw_Data
B5: Participantes | D5: Puntos de Inicio | G5: Viajes ($ de transportación)
B6: Gaynell Lehrman | D6: Clarkson Town | H6: Dome Rock | I6: Orange Grove | J6: Lemon Field | K6: Sunken Hill | L6: Falken Woods | M6: Cronberg Gorge | N6: Mulhalla Falls | O6: Matier Range | P6: Lake Guideon | Q6: Red Creek | R6: Clarkson Town | S6: Boiling Pools
B7: Meda Maddix | G7: Dome Rock | H7: 0 | I7: 138 | J7: 201 | K7: 167 | L7: 180 | M7: 96 | N7: 92 | O7: 113 | P7: 114 | Q7: 187 | R7: 118 | S7: 119
B8: Keri Wetzel | D8: Ubicaciones | G8: Orange Grove | I8: 0 | J8: 186 | K8: 90 | L8: 152 | M8: 233 | N8: 168 | O8: 232 | P8: 100 | Q8: 208 | R8: 150 | S8: 210
B9: Shaunte Osorio | D9: Dome Rock | E9: 1 | G9: Lemon Field | J9: 0 | K9: 218 | L9: 137 | M9: 150 | N9: 133 | O9: 140 | P9: 216 | Q9: 214 | R9: 238 | S9: 105
B10: Ivana Hage | D10: Orange Grove | E10: 2 | G10: Sunken Hill | K10: 0 | L10: 104 | M10: 152 | N10: 165 | O10: 186 | P10: 137 | Q10: 225 | R10: 218 | S10: 230
B11: Shavonda Spooner | D11: Lemon Field | E11: 3 | G11: Falken Woods | L11: 0 | M11: 167 | N11: 141 | O11: 197 | P11: 195 | Q11: 149 | R11: 172 | S11: 189
B12: Bette Priddy | D12: Sunken Hill | E12: 4 | G12: Cronberg Gorge | M12: 0 | N12: 112 | O12: 243 | P12: 205 | Q12: 85 | R12: 237 | S12: 129
B13: Paulina Mckinny | D13: Falken Woods | E13: 5 | G13: Mulhalla Falls | N13: 0 | O13: 201 | P13: 189 | Q13: 219 | R13: 235 | S13: 222
B14: Sulema Hyre | D14: Cronberg Gorge | E14: 6 | G14: Matier Range | O14: 0 | P14: 138 | Q14: 152 | R14: 164 | S14: 222
B15: Christin Gladding | D15: Mulhalla Falls | E15: 7 | G15: Lake Guideon | P15: 0 | Q15: 188 | R15: 85 | S15: 88
B16: Ivelisse Ellenwood | D16: Matier Range | E16: 8 | G16: Red Creek | Q16: 0 | R16: 175 | S16: 85
B17: Senaida Glanz | D17: Lake Guideon | E17: 9 | G17: Clarkson Town | R17: 0 | S17: 152
B18: Ute Volpe | D18: Red Creek | E18: 10 | G18: Boiling Pools | S18: 0
B19: Tiana Munoz | D19: Clarkson Town | E19: 11
B20: Simona Baumeister | D20: Boiling Pools | E20: 12
B21: Emmie Baugher
B22: Dorthey Magruder
B23: Katharina Housman
B24: Lue Rocheleau
B25: Jenniffer Berumen
B26: Lashanda Pangborn
B27: Amal Bunt
B28: Taisha Kauppi
B29: Marylynn Emmer
B32: Competidora 1 | C32: Competidora 2 | D32: Fecha | E32: Ubicación | G32: Ronda
B33: Gaynell Lehrman | C33: Ivana Hage | D33: 42958 | E33: Dome Rock | G33: Round 1
B34: Keri Wetzel | C34: Bette Priddy | D34: 42958 | E34: Orange Grove | G34: Round 2
B35: Meda Maddix | C35: Shavonda Spooner | D35: 42959 | E35: Lemon Field | G35: Round 3
B36: Shaunte Osorio | C36: Paulina Mckinny | D36: 42959 | E36: Sunken Hill | G36: Round 4
B37: Sulema Hyre | C37: Ute Volpe | D37: 42960 | E37: Falken Woods | G37: Round 1
B38: Ivelisse Ellenwood | C38: Simona Baumeister | D38: 42960 | E38: Cronberg Gorge | G38: Round 2
B39: Christin Gladding | C39: Tiana Munoz | D39: 42961 | E39: Mulhalla Falls | G39: Round 3
B40: Senaida Glanz | C40: Emmie Baugher | D40: 42961 | E40: Matier Range | G40: Round 4
B41: Dorthey Magruder | C41: Lashanda Pangborn | D41: 42962 | E41: Lake Guideon | G41: Round 1
B42: Lue Rocheleau | C42: Taisha Kauppi | D42: 42962 | E42: Red Creek | G42: Round 2
B43: Katharina Housman | C43: Amal Bunt | D43: 42963 | E43: Clarkson Town | G43: Round 3
B44: Jenniffer Berumen | C44: Marylynn Emmer | D44: 42963 | E44: Boiling Pools | G44: Round 4
... B99: Gaynell Lehrman | C99: Meda Maddix | D99: 42994 | E99: Mulhalla Falls | G99: Finals
